2025-04-18 12:23:59,657 - root - INFO - ==================================================
2025-04-18 12:23:59,658 - root - INFO - Application starting up
2025-04-18 12:23:59,658 - root - INFO - Log file: logs/app_20250418_122359.log
2025-04-18 12:23:59,660 - root - INFO - ==================================================
2025-04-18 12:23:59,694 - root - INFO - Memory database initialized successfully
2025-04-18 12:23:59,716 - werkzeug - WARNING -  * Debugger is active!
2025-04-18 12:23:59,720 - werkzeug - INFO -  * Debugger PIN: 676-759-043
2025-04-18 12:24:22,540 - werkzeug - INFO - 172.21.0.1 - - [18/Apr/2025 12:24:22] "GET /swagger-ui/ HTTP/1.1" 200 -
2025-04-18 12:24:22,595 - werkzeug - INFO - 172.21.0.1 - - [18/Apr/2025 12:24:22] "GET /flask-apispec/static/swagger-ui-standalone-preset.js HTTP/1.1" 200 -
2025-04-18 12:24:22,595 - werkzeug - INFO - 172.21.0.1 - - [18/Apr/2025 12:24:22] "GET /flask-apispec/static/swagger-ui-bundle.js HTTP/1.1" 200 -
2025-04-18 12:24:22,598 - werkzeug - INFO - 172.21.0.1 - - [18/Apr/2025 12:24:22] "GET /flask-apispec/static/swagger-ui.css HTTP/1.1" 200 -
2025-04-18 12:24:22,754 - werkzeug - INFO - 172.21.0.1 - - [18/Apr/2025 12:24:22] "GET /swagger.json HTTP/1.1" 200 -
2025-04-18 12:24:22,853 - werkzeug - INFO - 172.21.0.1 - - [18/Apr/2025 12:24:22] "GET /flask-apispec/static/favicon-32x32.png HTTP/1.1" 200 -
2025-04-18 12:24:33,100 - root - INFO - Received prompt: Design a cyberpunk city skyline at night
2025-04-18 12:24:33,101 - root - INFO - Using default app IDs: ['f0997a01-d6d3-a5fe-53d8-561300318557', '69543f29-4d41-4afc-7f29-3d51591f11eb']
2025-04-18 12:24:35,232 - root - ERROR - [f0997a01-d6d3-a5fe-53d8-561300318557] Initialization failed: HTTPSConnectionPool(host='f0997a01-d6d3-a5fe-53d8-561300318557', port=443): Max retries exceeded with url: /manifest (Caused by NameResolutionError("<urllib3.connection.HTTPSConnection object at 0x7f34fa546b60>: Failed to resolve 'f0997a01-d6d3-a5fe-53d8-561300318557' ([Errno -2] Name or service not known)"))
2025-04-18 12:24:37,318 - root - ERROR - [69543f29-4d41-4afc-7f29-3d51591f11eb] Initialization failed: HTTPSConnectionPool(host='69543f29-4d41-4afc-7f29-3d51591f11eb', port=443): Max retries exceeded with url: /manifest (Caused by NameResolutionError("<urllib3.connection.HTTPSConnection object at 0x7f34fa5478b0>: Failed to resolve '69543f29-4d41-4afc-7f29-3d51591f11eb' ([Errno -2] Name or service not known)"))
2025-04-18 12:24:37,319 - root - INFO - Processing prompt through pipeline
2025-04-18 12:24:37,331 - root - INFO - Enhancing prompt: Design a cyberpunk city skyline at night
2025-04-18 12:24:37,332 - root - INFO - Loading LLM model: TheBloke/Llama-2-7B-Chat-GGUF on cpu
2025-04-18 12:24:38,071 - root - ERROR - Failed to initialize GGUF model: 404 Client Error. (Request ID: Root=1-68024486-2dd7b66974d095b262dd1d96;800d3ab4-fc29-4202-9caf-f3d927887ac7)

Entry Not Found for url: https://huggingface.co/TheBloke/Llama-2-7B-Chat-GGUF/resolve/main/model.gguf.
Traceback (most recent call last):
  File "/usr/local/lib/python3.10/site-packages/huggingface_hub/utils/_http.py", line 409, in hf_raise_for_status
    response.raise_for_status()
  File "/usr/local/lib/python3.10/site-packages/requests/models.py", line 1021, in raise_for_status
    raise HTTPError(http_error_msg, response=self)
requests.exceptions.HTTPError: 404 Client Error: Not Found for url: https://huggingface.co/TheBloke/Llama-2-7B-Chat-GGUF/resolve/main/model.gguf

The above exception was the direct cause of the following exception:

Traceback (most recent call last):
  File "/app/app/llm_manager.py", line 96, in _initialize_gguf_model
    model_path = hf_hub_download(
  File "/usr/local/lib/python3.10/site-packages/huggingface_hub/utils/_validators.py", line 114, in _inner_fn
    return fn(*args, **kwargs)
  File "/usr/local/lib/python3.10/site-packages/huggingface_hub/file_download.py", line 961, in hf_hub_download
    return _hf_hub_download_to_cache_dir(
  File "/usr/local/lib/python3.10/site-packages/huggingface_hub/file_download.py", line 1024, in _hf_hub_download_to_cache_dir
    (url_to_download, etag, commit_hash, expected_size, xet_file_data, head_call_error) = _get_metadata_or_catch_error(
  File "/usr/local/lib/python3.10/site-packages/huggingface_hub/file_download.py", line 1484, in _get_metadata_or_catch_error
    metadata = get_hf_file_metadata(
  File "/usr/local/lib/python3.10/site-packages/huggingface_hub/utils/_validators.py", line 114, in _inner_fn
    return fn(*args, **kwargs)
  File "/usr/local/lib/python3.10/site-packages/huggingface_hub/file_download.py", line 1401, in get_hf_file_metadata
    r = _request_wrapper(
  File "/usr/local/lib/python3.10/site-packages/huggingface_hub/file_download.py", line 285, in _request_wrapper
    response = _request_wrapper(
  File "/usr/local/lib/python3.10/site-packages/huggingface_hub/file_download.py", line 309, in _request_wrapper
    hf_raise_for_status(response)
  File "/usr/local/lib/python3.10/site-packages/huggingface_hub/utils/_http.py", line 420, in hf_raise_for_status
    raise _format(EntryNotFoundError, message, response) from e
huggingface_hub.errors.EntryNotFoundError: 404 Client Error. (Request ID: Root=1-68024486-2dd7b66974d095b262dd1d96;800d3ab4-fc29-4202-9caf-f3d927887ac7)

Entry Not Found for url: https://huggingface.co/TheBloke/Llama-2-7B-Chat-GGUF/resolve/main/model.gguf.
2025-04-18 12:24:38,074 - root - ERROR - Failed to initialize LLM: 404 Client Error. (Request ID: Root=1-68024486-2dd7b66974d095b262dd1d96;800d3ab4-fc29-4202-9caf-f3d927887ac7)

Entry Not Found for url: https://huggingface.co/TheBloke/Llama-2-7B-Chat-GGUF/resolve/main/model.gguf.
Traceback (most recent call last):
  File "/usr/local/lib/python3.10/site-packages/huggingface_hub/utils/_http.py", line 409, in hf_raise_for_status
    response.raise_for_status()
  File "/usr/local/lib/python3.10/site-packages/requests/models.py", line 1021, in raise_for_status
    raise HTTPError(http_error_msg, response=self)
requests.exceptions.HTTPError: 404 Client Error: Not Found for url: https://huggingface.co/TheBloke/Llama-2-7B-Chat-GGUF/resolve/main/model.gguf

The above exception was the direct cause of the following exception:

Traceback (most recent call last):
  File "/app/app/llm_manager.py", line 73, in initialize
    self._initialize_gguf_model()
  File "/app/app/llm_manager.py", line 96, in _initialize_gguf_model
    model_path = hf_hub_download(
  File "/usr/local/lib/python3.10/site-packages/huggingface_hub/utils/_validators.py", line 114, in _inner_fn
    return fn(*args, **kwargs)
  File "/usr/local/lib/python3.10/site-packages/huggingface_hub/file_download.py", line 961, in hf_hub_download
    return _hf_hub_download_to_cache_dir(
  File "/usr/local/lib/python3.10/site-packages/huggingface_hub/file_download.py", line 1024, in _hf_hub_download_to_cache_dir
    (url_to_download, etag, commit_hash, expected_size, xet_file_data, head_call_error) = _get_metadata_or_catch_error(
  File "/usr/local/lib/python3.10/site-packages/huggingface_hub/file_download.py", line 1484, in _get_metadata_or_catch_error
    metadata = get_hf_file_metadata(
  File "/usr/local/lib/python3.10/site-packages/huggingface_hub/utils/_validators.py", line 114, in _inner_fn
    return fn(*args, **kwargs)
  File "/usr/local/lib/python3.10/site-packages/huggingface_hub/file_download.py", line 1401, in get_hf_file_metadata
    r = _request_wrapper(
  File "/usr/local/lib/python3.10/site-packages/huggingface_hub/file_download.py", line 285, in _request_wrapper
    response = _request_wrapper(
  File "/usr/local/lib/python3.10/site-packages/huggingface_hub/file_download.py", line 309, in _request_wrapper
    hf_raise_for_status(response)
  File "/usr/local/lib/python3.10/site-packages/huggingface_hub/utils/_http.py", line 420, in hf_raise_for_status
    raise _format(EntryNotFoundError, message, response) from e
huggingface_hub.errors.EntryNotFoundError: 404 Client Error. (Request ID: Root=1-68024486-2dd7b66974d095b262dd1d96;800d3ab4-fc29-4202-9caf-f3d927887ac7)

Entry Not Found for url: https://huggingface.co/TheBloke/Llama-2-7B-Chat-GGUF/resolve/main/model.gguf.
2025-04-18 12:24:38,076 - root - WARNING - Initializing fallback model (GPT-2 small)
2025-04-18 12:24:46,418 - huggingface_hub.file_download - WARNING - Xet Storage is enabled for this repo, but the 'hf_xet' package is not installed. Falling back to regular HTTP download. For better performance, install the package with: `pip install huggingface_hub[hf_xet]` or `pip install hf_xet`
2025-04-18 12:25:21,848 - root - INFO - Fallback model initialized successfully
2025-04-18 12:25:36,510 - root - ERROR - Error enhancing prompt: 'list' object has no attribute 'strip'
Traceback (most recent call last):
  File "/app/app/llm_manager.py", line 253, in enhance_prompt
    enhanced_prompt = generated_text[len(input_text):].strip()
AttributeError: 'list' object has no attribute 'strip'
2025-04-18 12:25:36,511 - root - INFO - Using fallback prompt: Design a cyberpunk city skyline at night with dramatic lighting, detailed textures, and vibrant colors
2025-04-18 12:25:36,512 - root - INFO - Generating image from prompt: Design a cyberpunk city skyline at night with dramatic lighting, detailed textures, and vibrant colors
2025-04-18 12:25:36,513 - root - ERROR - Error in pipeline: Input schema not found for app ID: f0997a01-d6d3-a5fe-53d8-561300318557
2025-04-18 12:25:36,514 - root - ERROR - Pipeline error: Input schema not found for app ID: f0997a01-d6d3-a5fe-53d8-561300318557
2025-04-18 12:25:36,515 - root - INFO - Response prepared: 90 characters
2025-04-18 12:25:36,518 - werkzeug - INFO - 172.21.0.1 - - [18/Apr/2025 12:25:36] "POST /execute HTTP/1.1" 200 -
